Workbook

Sheet Lab Diamond Jewelry
A1: LAB DIAMOND JEWELRY — 18K GOLD & 925 STERLING SILVER
A2: Cheapest option kept per design · Listed prices are the sites’ RETAIL prices · Set your wholesale discount, costs and profit % on the Pricing sheet — every figure below recalculates
A3: # | B3: Photo | C3: Product Name | D3: Category | E3: Description | F3: Metal | G3: Stone | H3: Weight (ct) | I3: Weight / Size (as stated) | J3: Stone Spec | K3: Listed Price (USD) retail on the site | L3: Your Cost (USD) after wholesale discount | M3: Landed Cost (SAR) incl. shipping, customs, fees | N3: FINAL PRICE (SAR) | O3: Profit (SAR) | P3: Product Link | Q3: Source | R3: Image URL | S3: Variants Merged
A4: 1 | C4: Round Lab Diamond Pave Force Rope Chain Bracelet | D4: Bracelet | E4: Stone Spec: Round Cut Lab Diamond DEF VS, 0.78 ct tw Please note, kindly specify your bracelet size in the remarks when placing the order. If you have any special requests for this design (such as metal, gemstone, or design details), please contact our advisor for customization. Description Bold and contemporary, this force rope chain bracelet features shimmering round lab diamonds in a refined pavé setting , combining the strength of classic chain styling with elevated fine jewelry brilliance. The intertwined rope-inspired links create rich texture and dimension, giving the piece a powerful… | F4: 925 Sterling Silver | G4: Lab Grown Diamond | H4: 0.78 | I4: 0.78 ct | J4: 0.78 ct tw round cut DEF VVS-VS | K4: 1063.2 | L4: =K4*(1-Pricing!$B$4) | M4: =L4*Pricing!$B$9*(1+Pricing!$B$6+Pricing!$B$7)+Pricing!$B$5 | N4: =M4*(1+Pricing!$B$8) | O4: =N4-M4 | P4: View Product | Q4: Fiorese Jewelry | R4: Open Image | S4: 1
A5: 2 | C5: Round Lab Diamond Heart Pendant Charm Bracelet | D5: Bracelet | E5: Stone Spec: Round Cut Lab Diamond DEF VS Please note, kindly specify your bracelet size in the remarks when placing the order. If you have any special requests for this design (such as metal, gemstone, or design details), please contact our advisor for customization. Description Sweet and refined, this charm bracelet features a delicate chain accented with a heart-shaped pendant adorned with round lab diamonds , symbolizing love with a soft, radiant sparkle. The round diamonds add timeless brilliance, while the heart motif brings a romantic and meaningful touch. The lightweight chain… | F5: 18K Gold | G5: Lab Grown Diamond | I5: 2mm (per stone) | J5: 4 pieces 2mm + 13 pieces 1mm DEF VS | K5: 1204 | L5: =K5*(1-Pricing!$B$4) | M5: =L5*Pricing!$B$9*(1+Pricing!$B$6+Pricing!$B$7)+Pricing!$B$5 | N5: =M5*(1+Pricing!$B$8) | O5: =N5-M5 | P5: View Product | Q5: Fiorese Jewelry | R5: Open Image | S5: 1
A6: 3 | C6: 3.5mm Round Lab Diamond 3-Stone Bezel-Set Adjustable Station Bracelet | D6: Bracelet | E6: Stone Spec: 3.5mm Round Cut Lab Diamond, DEF VS, about 0.45 ct tw Please note, kindly specify your bracelet size in the remarks when placing the order. If you have any special requests for this design (such as metal, gemstone, or design details), please contact our advisor for customization. Description Delicate and effortlessly refined, this adjustable station bracelet features three 3.5mm round lab diamonds , thoughtfully spaced along a fine chain to create a balanced and airy silhouette. The trio of stones symbolizes harmony and continuity, adding subtle meaning to its elegant design.… | F6: 18K Gold | G6: Lab Grown Diamond | H6: 0.45 | I6: 0.45 ct | J6: 3 pieces of 3.5mm round cut | K6: 1300.8 | L6: =K6*(1-Pricing!$B$4) | M6: =L6*Pricing!$B$9*(1+Pricing!$B$6+Pricing!$B$7)+Pricing!$B$5 | N6: =M6*(1+Pricing!$B$8) | O6: =N6-M6 | P6: View Product | Q6: Fiorese Jewelry | R6: Open Image | S6: 1
A7: 4 | C7: Round Lab Diamond Toi et Moi Pendant Chain Bracelet | D7: Bracelet | E7: Stone Spec: 1.2mm Radiant Cut Lab Diamond DEF VS, about 0.17 ct tw Pendant Size: 25*6.6mm Please note, kindly specify your bracelet size in the remarks when placing the order. If you have any special requests for this design (such as metal, gemstone, or design details), please contact our advisor for customization. Description Refined and meaningful, this chain bracelet features a distinctive Toi-et-Moi pendant , pairing a round lab diamond centerpiece with a rectangular ring motif set with pavé lab diamonds . The interplay of shapes symbolizes two elements in harmony—soft brilliance meeting… | F7: 18K Gold | G7: Lab Grown Diamond | H7: 0.17 | I7: 0.17 ct | J7: 22 pieces of 1.2mm round cut DEF VS | K7: 1423.2 | L7: =K7*(1-Pricing!$B$4) | M7: =L7*Pricing!$B$9*(1+Pricing!$B$6+Pricing!$B$7)+Pricing!$B$5 | N7: =M7*(1+Pricing!$B$8) | O7: =N7-M7 | P7: View Product | Q7: Fiorese Jewelry | R7: Open Image | S7: 1
A8: 5 | C8: 3mm Round Lab Diamond Bezel-Set Station Bracelet | D8: Bracelet | E8: Stone Spec: 3mm Round Cut Lab Diamond, DEF VS, about 0.77 ct tw Please note, kindly specify your bracelet size in the remarks when placing the order. If you have any special requests for this design (such as metal, gemstone, or design details), please contact our advisor for customization. Description Clean and effortlessly refined, this station bracelet features 3mm round lab diamonds delicately spaced along a fine chain, creating a light, balanced silhouette with subtle, continuous sparkle. The station design offers an airy, modern feel that complements both everyday wear and layered… | F8: 18K Gold | G8: Lab Grown Diamond | H8: 0.77 | I8: 0.77 ct | J8: 7 pieces of 3mm DEF VS | K8: 1423.2 | L8: =K8*(1-Pricing!$B$4) | M8: =L8*Pricing!$B$9*(1+Pricing!$B$6+Pricing!$B$7)+Pricing!$B$5 | N8: =M8*(1+Pricing!$B$8) | O8: =N8-M8 | P8: View Product | Q8: Fiorese Jewelry | R8: Open Image | S8: 1
A9: 6 | C9: 3mm Round Lab Diamond 5-Stone Bezel-Set Adjustable Station Bracelet | D9: Bracelet | E9: Stone Spec: 3mm Round Cut Lab Diamond, DEF VS, about 0.5 ct tw Please note, kindly specify your bracelet size in the remarks when placing the order. If you have any special requests for this design (such as metal, gemstone, or design details), please contact our advisor for customization. Description Light, refined, and effortlessly wearable, this adjustable station bracelet features five 3mm round lab diamonds , evenly spaced along a fine chain to create a graceful, balanced silhouette. The five-stone arrangement adds a subtle rhythm of sparkle while maintaining a clean, minimalist… | F9: 18K Gold | G9: Lab Grown Diamond | H9: 0.5 | I9: 0.5 ct | J9: 5 pieces of 3mm round cut | K9: 1473.6 | L9: =K9*(1-Pricing!$B$4) | M9: =L9*Pricing!$B$9*(1+Pricing!$B$6+Pricing!$B$7)+Pricing!$B$5 | N9: =M9*(1+Pricing!$B$8) | O9: =N9-M9 | P9: View Product | Q9: Fiorese Jewelry | R9: Open Image | S9: 1
A10: 7 | C10: Round Lab Diamond Leaf-Cluster Chain Bracelet | D10: Bracelet | E10: Stone Spec: Round Cut Lab Diamond DEF VS, about 0.3 ct tw Cluster Length: 32mm Please note, kindly specify your bracelet size in the remarks when placing the order. If you have any special requests for this design (such as metal, gemstone, or design details), please contact our advisor for customization. Description Graceful and organically inspired, this chain bracelet features clusters of round lab diamonds arranged in a delicate leaf motif , creating a soft, flowing pattern along the wrist. Each cluster evokes the natural beauty of foliage, blending structure with gentle movement. The… | F10: 18K Gold | G10: Lab Grown Diamond | H10: 0.3 | I10: 0.3 ct | J10: Round Cut DEF VS | K10: 1703.2 | L10: =K10*(1-Pricing!$B$4) | M10: =L10*Pricing!$B$9*(1+Pricing!$B$6+Pricing!$B$7)+Pricing!$B$5 | N10: =M10*(1+Pricing!$B$8) | O10: =N10-M10 | P10: View Product | Q10: Fiorese Jewelry | R10: Open Image | S10: 1
A11: 8 | C11: Round Lab Diamond Viper-Inspired Bangle Bracelet | D11: Bracelet | E11: Stone Spec: Round Cut Lab Diamond DEF VS about 3.66 ct tw Please note, kindly specify your bracelet size in the remarks when placing the order. If you have any special requests for this design (such as metal, gemstone, or design details), please contact our advisor for customization. Description Bold, sculptural, and undeniably captivating, this viper-inspired bangle bracelet features shimmering round lab diamonds arranged within a sleek serpentine silhouette that wraps gracefully around the wrist. Inspired by the fluid movement and striking elegance of a serpent, the design embodies both… | F11: 925 Sterling Silver | G11: Lab Grown Diamond | H11: 3.66 | I11: 3.66 ct | J11: Round Lab Diamond DEF VVS-VS | K11: 1809.6 | L11: =K11*(1-Pricing!$B$4) | M11: =L11*Pricing!$B$9*(1+Pricing!$B$6+Pricing!$B$7)+Pricing!$B$5 | N11: =M11*(1+Pricing!$B$8) | O11: =N11-M11 | P11: View Product | Q11: Fiorese Jewelry | R11: Open Image | S11: 1
A12: 9 | C12: Round Lab Diamond Star Bezel-Set Station Bracelet | D12: Bracelet | E12: Stone Spec: Round Cut Lab Diamond DEF VS Stone Size Guide (Based on 6" Bracelet) Total Carat Weight ~1.62 ct tw Please note, kindly specify your bracelet size in the remarks when placing the order. If you have any special requests for this design (such as metal, gemstone, or design details), please contact our advisor for customization. Description Whimsical and refined, this station bracelet features round lab diamonds framed in distinctive star-shaped bezel settings , creating a celestial-inspired design that feels both playful and sophisticated. Each star gently highlights the diamond at… | F12: 18K Gold | G12: Lab Grown Diamond | H12: 1.62 | I12: 1.62 ct | J12: 1.8mm round cut lab diamond DEF VVS-VS | K12: 2132.8 | L12: =K12*(1-Pricing!$B$4) | M12: =L12*Pricing!$B$9*(1+Pricing!$B$6+Pricing!$B$7)+Pricing!$B$5 | N12: =M12*(1+Pricing!$B$8) | O12: =N12-M12 | P12: View Product | Q12: Fiorese Jewelry | R12: Open Image | S12: 2
A13: 10 | C13: Round Lab Diamond Ring-Shaped Pave Pendant Chain Bracelet | D13: Bracelet | E13: Stone Spec: 1.5mm Round Cut Lab Diamond DEF VS, about 0.57 ct tw Pendant Size: 23mm Please note, kindly specify your bracelet size in the remarks when placing the order. If you have any special requests for this design (such as metal, gemstone, or design details), please contact our advisor for customization. Description Modern and symbolic, this chain bracelet features a refined ring-shaped pendant set with round lab diamonds , creating a continuous circle of light that represents unity and eternity. The clean, circular silhouette adds a contemporary elegance with meaningful depth. The… | F13: 18K Gold | G13: Lab Grown Diamond | H13: 0.57 | I13: 0.57 ct | J13: 38 pieces of 1.5mm round cut DEF VVS-VS | K13: 2873.6 | L13: =K13*(1-Pricing!$B$4) | M13: =L13*Pricing!$B$9*(1+Pricing!$B$6+Pricing!$B$7)+Pricing!$B$5 | N13: =M13*(1+Pricing!$B$8) | O13: =N13-M13 | P13: View Product | Q13: Fiorese Jewelry | R13: Open Image | S13: 1
A14: 11 | C14: Round Lab Diamond Fancy-Shape Station Chain Bracelet | D14: Bracelet | E14: Stone Spec: Round Cut Lab Diamond, DEF VS, about 2 ct tw Please note, kindly specify your bracelet size in the remarks when placing the order. If you have any special requests for this design (such as metal, gemstone, or design details), please contact our advisor for customization. Description Playful yet refined, this station chain bracelet features a harmonious mix of round lab diamonds and fancy-shaped accents , creating a dynamic interplay of light and form along a delicate chain. The varied silhouettes add visual interest while maintaining a balanced, elegant composition. Each diamond… | F14: 18K Gold | G14: Lab Grown Diamond | H14: 2 | I14: 2 ct | J14: Round Cut DEF VS about 2 ct tw | K14: 2926.4 | L14: =K14*(1-Pricing!$B$4) | M14: =L14*Pricing!$B$9*(1+Pricing!$B$6+Pricing!$B$7)+Pricing!$B$5 | N14: =M14*(1+Pricing!$B$8) | O14: =N14-M14 | P14: View Product | Q14: Fiorese Jewelry | R14: Open Image | S14: 1
A15: 12 | C15: Round Lab Diamond Pave Force Rope Chain Bracelet | D15: Bracelet | E15: Stone Spec: Round Cut Lab Diamond DEF VS, 0.78 ct tw Please note, kindly specify your bracelet size in the remarks when placing the order. If you have any special requests for this design (such as metal, gemstone, or design details), please contact our advisor for customization. Description Bold and contemporary, this force rope chain bracelet features shimmering round lab diamonds in a refined pavé setting , combining the strength of classic chain styling with elevated fine jewelry brilliance. The intertwined rope-inspired links create rich texture and dimension, giving the piece a powerful… | F15: 18K Gold | G15: Lab Grown Diamond | H15: 0.78 | I15: 0.78 ct | J15: 0.78 ct tw round cut DEF VVS-VS | K15: 3378.4 | L15: =K15*(1-Pricing!$B$4) | M15: =L15*Pricing!$B$9*(1+Pricing!$B$6+Pricing!$B$7)+Pricing!$B$5 | N15: =M15*(1+Pricing!$B$8) | O15: =N15-M15 | P15: View Product | Q15: Fiorese Jewelry | R15: Open Image | S15: 1
A16: 13 | C16: Men's Iced-Out Cuban Link Bracelet with Round Lab Diamonds | D16: Bracelet | E16: Stone Spec: Round Cut Lab Diamond DEF VS Stone Size Guide (Based on 7.8" Bracelet) Total Carat Weight ~9.2 ct tw Please note, kindly specify your bracelet size in the remarks when placing the order. If you have any special requests for this design (such as metal, gemstone, or design details), please contact our advisor for customization. Description Bold, powerful, and unapologetically luxurious, this men’s Cuban link bracelet is fully adorned with round lab diamonds in an iced-out pavé design, creating an intense display of brilliance from every angle. The iconic Cuban link silhouette… | F16: 925 Sterling Silver | G16: Lab Grown Diamond | H16: 9.2 | I16: 9.2 ct | J16: Round Lab Diamond DEF VS | K16: 3603.2 | L16: =K16*(1-Pricing!$B$4) | M16: =L16*Pricing!$B$9*(1+Pricing!$B$6+Pricing!$B$7)+Pricing!$B$5 | N16: =M16*(1+Pricing!$B$8) | O16: =N16-M16 | P16: View Product | Q16: Fiorese Jewelry | R16: Open Image | S16: 1
A17: 14 | C17: Round Lab Diamond Prong Basket Cluster Bracelet | D17: Bracelet | E17: Stone Spec: Round Cut Lab Diamond DEF VS Adjustable Chain Length: 2 inches Stone Size Guide (Based on 7" Bracelet) Total Carat Weight ~4.96 ct tw Please note, kindly specify your bracelet size in the remarks when placing the order. If you have any special requests for this design (such as metal, gemstone, or design details), please contact our advisor for customization. Description Radiant and full of dimension, this cluster bracelet features groups of round lab diamonds arranged in elegant clusters, creating the illusion of larger stones with amplified brilliance. Each cluster is secured in… | F17: 18K Gold | G17: Lab Grown Diamond | H17: 4.96 | I17: 4.96 ct | J17: Round cut lab diamond DEF VS | K17: 4388 | L17: =K17*(1-Pricing!$B$4) | M17: =L17*Pricing!$B$9*(1+Pricing!$B$6+Pricing!$B$7)+Pricing!$B$5 | N17: =M17*(1+Pricing!$B$8) | O17: =N17-M17 | P17: View Product | Q17: Fiorese Jewelry | R17: Open Image | S17: 1
... A19: 16 | C19: Round Cut Lab Diamond 14-Stone Open Bangle Bracelet | D19: Bracelet | E19: Stone Spec: 3.5mm Round Cut Lab Diamond DEF VS, about 2.24 ct tw Width: 2.4mm Thickness: 1.8mm Please note, kindly specify your bracelet size in the remarks when placing the order. If you have any special requests for this design (such as metal, gemstone, or design details), please contact our advisor for customization. Description Elegant and strikingly modern, this open bangle bracelet features 14 round cut lab diamonds arranged along the curved silhouette for a balanced display of brilliance and sophistication. The open design creates a refined contemporary look while allowing the… | F19: 18K Gold | G19: Lab Grown Diamond | H19: 2.24 | I19: 2.24 ct | J19: 14 pieces of round cut lab diamond DEF VVS-VS about 2.24 ct | K19: 5404.8 | L19: =K19*(1-Pricing!$B$4) | M19: =L19*Pricing!$B$9*(1+Pricing!$B$6+Pricing!$B$7)+Pricing!$B$5 | N19: =M19*(1+Pricing!$B$8) | O19: =N19-M19 | P19: View Product | Q19: Fiorese Jewelry | R19: Open Image | S19: 1
A20: 17 | C20: 2.5mm Gemstone Four-Leaf Clover Station Bracelet with Millegrain Bezel | D20: Bracelet | E20: Stone Spec: Round Cut Lab Diamond, DEF VS, and Round Gemstone Please note, kindly specify your bracelet size in the remarks when placing the order. If you have any special requests for this design (such as metal, gemstone, or design details), please contact our advisor for customization. Description Inspired by the timeless symbolism of luck and happiness, this 18K yellow gold station bracelet features a series of delicate four-leaf clover motifs, each formed by four 2.5mm round-cut gemstones. The thoughtfully spaced station design creates a light, graceful silhouette that rests beautifully… | F20: 18K Gold | G20: Lab Grown Diamond | I20: 2.5mm (per stone) | J20: Round Cut Lab Diamond DEF VS and Round Gemstone | K20: 5715.2 | L20: =K20*(1-Pricing!$B$4) | M20: =L20*Pricing!$B$9*(1+Pricing!$B$6+Pricing!$B$7)+Pricing!$B$5 | N20: =M20*(1+Pricing!$B$8) | O20: =N20-M20 | P20: View Product | Q20: Fiorese Jewelry | R20: Open Image | S20: 1
A21: 18 | C21: Oval Cut Lab Diamond Bezel-Set Bangle Bracelet | D21: Bracelet | E21: Stone Spec: Oval Cut Lab Diamond DEF VS, about 2.16 ct tw Please note, kindly specify your bracelet size in the remarks when placing the order. If you have any special requests for this design (such as metal, gemstone, or design details), please contact our advisor for customization. Description Elegant and contemporary, this bangle bracelet features a refined arrangement of oval cut lab diamonds , celebrated for their elongated silhouette and soft, brilliant sparkle. The graceful proportions of the oval cuts create a flattering, fluid line across the wrist with timeless sophistication. Each… | F21: 18K Gold | G21: Lab Grown Diamond | H21: 2.16 | I21: 2.16 ct | J21: 12 pieces of 3*5mm oval cut DEF VS | K21: 8018.4 | L21: =K21*(1-Pricing!$B$4) | M21: =L21*Pricing!$B$9*(1+Pricing!$B$6+Pricing!$B$7)+Pricing!$B$5 | N21: =M21*(1+Pricing!$B$8) | O21: =N21-M21 | P21: View Product | Q21: Fiorese Jewelry | R21: Open Image | S21: 1
A22: 19 | C22: Round Lab Diamond Viper-Inspired Bangle Bracelet | D22: Bracelet | E22: Stone Spec: Round Cut Lab Diamond DEF VS about 3.66 ct tw Please note, kindly specify your bracelet size in the remarks when placing the order. If you have any special requests for this design (such as metal, gemstone, or design details), please contact our advisor for customization. Description Bold, sculptural, and undeniably captivating, this viper-inspired bangle bracelet features shimmering round lab diamonds arranged within a sleek serpentine silhouette that wraps gracefully around the wrist. Inspired by the fluid movement and striking elegance of a serpent, the design embodies both… | F22: 18K Gold | G22: Lab Grown Diamond | H22: 3.66 | I22: 3.66 ct | J22: Round Lab Diamond DEF VVS-VS | K22: 10534.4 | L22: =K22*(1-Pricing!$B$4) | M22: =L22*Pricing!$B$9*(1+Pricing!$B$6+Pricing!$B$7)+Pricing!$B$5 | N22: =M22*(1+Pricing!$B$8) | O22: =N22-M22 | P22: View Product | Q22: Fiorese Jewelry | R22: Open Image | S22: 1
A23: 20 | C23: 24 CT TW Cushion Cut Lab Diamond 4-Claw Prong Basket Station Bracelet | D23: Bracelet | E23: Stone Spec: 6.5mm Cushion Cut Lab Diamond DEF VS Stone Size Guide (Based on 7" Bracelet) Total Carat Weight ~24 ct tw Please note, kindly specify your bracelet size in the remarks when placing the order. If you have any special requests for this design (such as metal, gemstone, or design details), please contact our advisor for customization. Description Bold, luminous, and unapologetically luxurious, this station bracelet features an impressive total of 24 ct tw cushion cut lab diamonds , each chosen for its soft square silhouette and rich, brilliant sparkle. The cushion cut’s rounded… | F23: 18K Gold | G23: Lab Grown Diamond | H23: 24 | I23: 24 ct | J23: 24 pieces of 6.5*6.5mm cushion cut lab diamond DEF VS about | K23: 10956.8 | L23: =K23*(1-Pricing!$B$4) | M23: =L23*Pricing!$B$9*(1+Pricing!$B$6+Pricing!$B$7)+Pricing!$B$5 | N23: =M23*(1+Pricing!$B$8) | O23: =N23-M23 | P23: View Product | Q23: Fiorese Jewelry | R23: Open Image | S23: 1
A24: 21 | C24: Round and Princess Cut Lab Diamond Bezel-Set Bangle Bracelet | D24: Bracelet | E24: Stone Spec: Princess Cut and Round Lab Diamond DEF VS, about 0.87 ct tw Please note, kindly specify your bracelet size in the remarks when placing the order. If you have any special requests for this design (such as metal, gemstone, or design details), please contact our advisor for customization. Description Modern and elegantly structured, this bangle bracelet features a refined combination of round and princess cut lab diamonds , creating a sophisticated contrast between soft brilliance and crisp geometric sparkle. The mixed-shape arrangement adds visual rhythm and contemporary character… | F24: 18K Gold | G24: Lab Grown Diamond | H24: 0.87 | I24: 0.87 ct | J24: Princess Cut and Round Lab Diamond DEF VS / about 0.87 ct tw | K24: 11013.6 | L24: =K24*(1-Pricing!$B$4) | M24: =L24*Pricing!$B$9*(1+Pricing!$B$6+Pricing!$B$7)+Pricing!$B$5 | N24: =M24*(1+Pricing!$B$8) | O24: =N24-M24 | P24: View Product | Q24: Fiorese Jewelry | R24: Open Image | S24: 1
A25: 22 | C25: Knight's Faith Pavé Lab Diamond Bracelet | D25: Bracelet | E25: Stone Spec: Round Cut Lab Diamond DEF VS Stone Size Guide (Based on 7" Bracelet) Total Carat Weight ~6.2 ct tw Please note, kindly specify your bracelet size in the remarks when placing the order. If you have any special requests for this design (such as metal, gemstone, or design details), please contact our advisor for customization. Description Bold, commanding, and richly detailed, the Knight’s Faith Pavé Lab Diamond Bracelet is designed to embody strength, confidence, and refined modern luxury. Adorned with shimmering pavé-set lab diamonds , the bracelet delivers continuous brilliance… | F25: 18K Gold | G25: Lab Grown Diamond | H25: 6.2 | I25: 6.2 ct | J25: Round cut DEF VS | K25: 20387.2 | L25: =K25*(1-Pricing!$B$4) | M25: =L25*Pricing!$B$9*(1+Pricing!$B$6+Pricing!$B$7)+Pricing!$B$5 | N25: =M25*(1+Pricing!$B$8) | O25: =N25-M25 | P25: View Product | Q25: Fiorese Jewelry | R25: Open Image | S25: 1
A26: 23 | C26: Men's Iced-Out Cuban Link Bracelet with Round Lab Diamonds | D26: Bracelet | E26: Stone Spec: Round Cut Lab Diamond DEF VS Stone Size Guide (Based on 7.8" Bracelet) Total Carat Weight ~9.2 ct tw Please note, kindly specify your bracelet size in the remarks when placing the order. If you have any special requests for this design (such as metal, gemstone, or design details), please contact our advisor for customization. Description Bold, powerful, and unapologetically luxurious, this men’s Cuban link bracelet is fully adorned with round lab diamonds in an iced-out pavé design, creating an intense display of brilliance from every angle. The iconic Cuban link silhouette… | F26: 18K Gold | G26: Lab Grown Diamond | H26: 9.2 | I26: 9.2 ct | J26: Round Lab Diamond DEF VS | K26: 39595.2 | L26: =K26*(1-Pricing!$B$4) | M26: =L26*Pricing!$B$9*(1+Pricing!$B$6+Pricing!$B$7)+Pricing!$B$5 | N26: =M26*(1+Pricing!$B$8) | O26: =N26-M26 | P26: View Product | Q26: Fiorese Jewelry | R26: Open Image | S26: 1
A27: 24 | C27: Colored Lab Gemstone Bracelet with 10×14mm Oval Lab Orange Sapphire | D27: Bracelet | E27: Stone Spec: 14*10mm Oval Lab Orange Sapphire and R ound Lab Colored Sapphire Stone Size Guide (Based on 6.5" Bracelet) Total Carat Weight ~15.5 ct tw Please note, kindly specify your bracelet size in the remarks when placing the order. If you have any special requests for this design (such as metal, gemstone, or design details), please contact our advisor for customization. Description Vivid and sophisticated, this colored gemstone bracelet showcases a striking 10×14mm oval lab orange sapphire , celebrated for its rich sunset-inspired hue and luminous brilliance. The elongated oval cut… | F27: 18K Gold | G27: Lab Grown Diamond | H27: 15.5 | I27: 15.5 ct | J27: 1.2mm round lab diamond DEF VVS-VS with 10*14mm oval lab sap | K27: 49124.8 | L27: =K27*(1-Pricing!$B$4) | M27: =L27*Pricing!$B$9*(1+Pricing!$B$6+Pricing!$B$7)+Pricing!$B$5 | N27: =M27*(1+Pricing!$B$8) | O27: =N27-M27 | P27: View Product | Q27: Fiorese Jewelry | R27: Open Image | S27: 1
A28: 25 | C28: Rose-Cut Lab Diamond Hook Earrings | D28: Earrings | E28: Stone Type: Lab Diamond Stone Spec: custom 5mm rose cut DEF VS If you have any special requests for this design (such as metal, gemstone, or design details), please contact our advisor for customization. Description Delicate and romantic, these hook earrings feature 5mm rose cut lab diamonds , known for their soft, domed facets and gentle, candlelit sparkle. The rose cut creates a subtle glow rather than sharp brilliance, giving the design a dreamy, antique-inspired feel. Suspended from a simple hook setting, the diamonds move gracefully with the wearer, catching light in a quiet, effortless… | F28: 18K Gold | G28: Lab Grown Diamond | I28: 5mm (per stone) | J28: 5mm rose cut DEF VS | K28: 968.24 | L28: =K28*(1-Pricing!$B$4) | M28: =L28*Pricing!$B$9*(1+Pricing!$B$6+Pricing!$B$7)+Pricing!$B$5 | N28: =M28*(1+Pricing!$B$8) | O28: =N28-M28 | P28: View Product | Q28: Fiorese Jewelry | R28: Open Image | S28: 1
A29: 26 | C29: Round-Cut Lab Diamond Halo Dangle Hook Earrings with Floating Center Stone | D29: Earrings | E29: Stone Type: Lab Diamond Center Stone: 5mm round cut DEF VS, about 1 ct tw Side Stone: 1.6mm round cut DEF VS, about 0.5 ct tw Height: 22.5mm Width: 11mm If you have any special requests for this design (such as metal, gemstone, or design details), please contact our advisor for customization. Description Elegant and full of movement, these hook earrings feature round-cut lab diamonds framed by a delicate halo setting , enhancing brilliance with a radiant circle of light. At the center, a movable diamond dangle adds graceful motion, allowing the stone to catch and reflect light from every… | F29: 18K Gold | G29: Lab Grown Diamond | H29: 0.5 | I29: 0.5 ct | J29: 2 pieces 0.5ct DEF VS + 30 pieces 1.6mm Round cut DEF VVS-VS | K29: 1425 | L29: =K29*(1-Pricing!$B$4) | M29: =L29*Pricing!$B$9*(1+Pricing!$B$6+Pricing!$B$7)+Pricing!$B$5 | N29: =M29*(1+Pricing!$B$8) | O29: =N29-M29 | P29: View Product | Q29: Fiorese Jewelry | R29: Open Image | S29: 1
A30: 27 | C30: Baguette- and Round-Cut Lab Diamond Ear Cuffs | D30: Earrings | E30: Stone Type: Lab Diamond Pave: 1.2mm round cut and 2*1.5mm baguette cut DEF VS, about 0.85 ct tw Inner Arc Length: 24.5mm Outer Arc Length: 31mm If you have any special requests for this design (such as metal, gemstone, or design details), please contact our advisor for customization. Description Modern and effortlessly chic, these ear cuffs feature a refined combination of baguette-cut and round-cut lab diamonds , creating a dynamic contrast of linear brilliance and soft sparkle. The mixed-cut design adds depth and dimension, wrapping the ear in a sleek, sculptural silhouette. Perfect for… | F30: 18K Gold | G30: Lab Grown Diamond | H30: 0.85 | I30: 0.85 ct | J30: 18 pieces 2*1.5mm Baguette cut + 50 pieces 1.2mm Round Cut D | K30: 2925.24 | L30: =K30*(1-Pricing!$B$4) | M30: =L30*Pricing!$B$9*(1+Pricing!$B$6+Pricing!$B$7)+Pricing!$B$5 | N30: =M30*(1+Pricing!$B$8) | O30: =N30-M30 | P30: View Product | Q30: Fiorese Jewelry | R30: Open Image | S30: 1
A31: 28 | C31: Round-Cut Lab Diamond Thin Eternity Ring | D31: Engagement Ring | E31: Stone Type: Lab Diamond Stone Spec: 1.3mm round cut DEF VS Band Width: 1.4mm Band Thickness: 1.6mm If you have any special requests for this design (such as metal, gemstone, or design details), please contact our advisor for customization. Description Delicate, refined, and effortlessly timeless, this thin eternity ring features a continuous circle of shimmering 1.3mm round-cut lab diamonds , creating a graceful ribbon of brilliance with understated sophistication. The slender silhouette offers a light, elegant presence that feels both modern and endlessly versatile. Each round diamond is… | F31: 18K Gold | G31: Lab Grown Diamond | I31: 1.3mm (per stone) | J31: 1.3mm Round Cut DEF VS | K31: 894.75 | L31: =K31*(1-Pricing!$B$4) | M31: =L31*Pricing!$B$9*(1+Pricing!$B$6+Pricing!$B$7)+Pricing!$B$5 | N31: =M31*(1+Pricing!$B$8) | O31: =N31-M31 | P31: View Product | Q31: Fiorese Jewelry | R31: Open Image | S31: 1
A32: 29 | C32: Heart-Cut Lab Diamond Solitaire Ring with Martini Setting | D32: Engagement Ring | E32: Stone Type: Lab Diamond Center Stone: 0.25ct heart cut DEF VS about Band Width: 1.3mm Band Thickness: 1.3mm If you have any special requests for this design (such as metal, gemstone, or design details), please contact our advisor for customization. Description Romantic yet refined, this heart-cut lab diamond solitaire ring features a delicate 3-prong martini setting paired with a sleek slim band , creating a design that feels both meaningful and effortlessly wearable. The martini-style base allows the diamond to sit low on the finger, giving the center stone a subtle floating appearance… | F32: 18K Gold | G32: Lab Grown Diamond | H32: 0.25 | I32: 0.25 ct | J32: 0.25ct heart cut DEF VS | K32: 1024.5 | L32: =K32*(1-Pricing!$B$4) | M32: =L32*Pricing!$B$9*(1+Pricing!$B$6+Pricing!$B$7)+Pricing!$B$5 | N32: =M32*(1+Pricing!$B$8) | O32: =N32-M32 | P32: View Product | Q32: Fiorese Jewelry | R32: Open Image | S32: 1
A33: 30 | C33: Fancy Pink Round Lab Diamond Slim Eternity Ring | D33: Engagement Ring | E33: Stone Type: Lab Diamond Stone Spec: 1.3mm round cut fancy pink VS Band Width: 1.5mm Band Thickness: 1.6mm If you have any special requests for this design (such as metal, gemstone, or design details), please contact our advisor for customization. Description Romantic, delicate, and effortlessly refined, this slim eternity ring features a continuous circle of luminous 1.3mm fancy pink round lab diamonds , creating a graceful ribbon of soft blush brilliance around the finger. The slender silhouette offers understated elegance while adding a subtle touch of rare color and feminine… | F33: 18K Gold | G33: Lab Grown Diamond | I33: 1.3mm (per stone) | J33: 1.3mm Fancy Pink Round Lab Diamond VS | K33: 1053.75 | L33: =K33*(1-Pricing!$B$4) | M33: =L33*Pricing!$B$9*(1+Pricing!$B$6+Pricing!$B$7)+Pricing!$B$5 | N33: =M33*(1+Pricing!$B$8) | O33: =N33-M33 | P33: View Product | Q33: Fiorese Jewelry | R33: Open Image | S33: 1
A34: 31 | C34: Round Lab Diamond Half Eternity Ring with Marquise-Shaped Millegrain Design | D34: Engagement Ring | E34: Stone Type: Lab Diamond Stone Spec: round cut DEF VS about 0.16 ct tw Band Width: 2mm Band Thickness: 1.5mm If you have any special requests for this design (such as metal, gemstone, or design details), please contact our advisor for customization. Description Romantic, intricate, and timelessly refined, this half eternity ring features shimmering round lab diamonds framed within elegant marquise-shaped millegrain detailing , creating a graceful composition inspired by antique fine jewelry artistry. The delicate marquise motifs introduce soft vintage character and refined architectural… | F34: 18K Gold | G34: Lab Grown Diamond | H34: 0.16 | I34: 0.16 ct | J34: 12 pieces of 1.5mm round cut DEF VS | K34: 1266.75 | L34: =K34*(1-Pricing!$B$4) | M34: =L34*Pricing!$B$9*(1+Pricing!$B$6+Pricing!$B$7)+Pricing!$B$5 | N34: =M34*(1+Pricing!$B$8) | O34: =N34-M34 | P34: View Product | Q34: Fiorese Jewelry | R34: Open Image | S34: 1
A35: 32 | C35: Round Lab Diamond Twist Ring Enhancer with Pavé | D35: Engagement Ring | E35: Stone Type: Lab Diamond Stone Spec: round cut DEF VS Band Width: 1.8mm Band Thickness: 1.8mm If you have any special requests for this design (such as metal, gemstone, or design details), please contact our advisor for customization. Description Elegant, romantic, and beautifully fluid, this ring enhancer features shimmering round lab diamonds woven through an intricate intertwined pavé band design , creating a graceful twisting silhouette filled with movement and brilliance. The sculptural curves wrap delicately around an engagement ring, adding layered sparkle and refined dimensional… | F35: 18K Gold | G35: Lab Grown Diamond | I35: 1.8mm (per stone) | J35: round cut DEF VS | K35: 1311.75 | L35: =K35*(1-Pricing!$B$4) | M35: =L35*Pricing!$B$9*(1+Pricing!$B$6+Pricing!$B$7)+Pricing!$B$5 | N35: =M35*(1+Pricing!$B$8) | O35: =N35-M35 | P35: View Product | Q35: Fiorese Jewelry | R35: Open Image | S35: 1
A36: 33 | C36: Round Lab Diamond V-Shaped Wedding Ring with Millegrain Micropavé | D36: Engagement Ring | E36: Stone Type: Lab Diamond Stone Spec: round cut DEF VS Band Width: 1.7mm Band Thickness: 1.5mm If you have any special requests for this design (such as metal, gemstone, or design details), please contact our advisor for customization. Description Romantic, refined, and intricately detailed, this V-shaped wedding ring features shimmering round lab diamonds accented by delicate millegrain micropavé craftsmanship , creating a graceful balance of vintage-inspired elegance and modern bridal sophistication. The contoured silhouette is designed to complement engagement rings beautifully while adding… | F36: 18K Gold | G36: Lab Grown Diamond | I36: 1.7mm (per stone) | J36: 21 pieces of round lab diamond DEF VS | K36: 1333.5 | L36: =K36*(1-Pricing!$B$4) | M36: =L36*Pricing!$B$9*(1+Pricing!$B$6+Pricing!$B$7)+Pricing!$B$5 | N36: =M36*(1+Pricing!$B$8) | O36: =N36-M36 | P36: View Product | Q36: Fiorese Jewelry | R36: Open Image | S36: 1
A37: 34 | C37: Round-Cut Lab Diamond V-Shaped Wedding Ring Enhancer with French Pavé | D37: Engagement Ring | E37: Stone Type: Lab Diamond Stone Spec: 1.8mm round cut DEF VS (3/4 pave ) Band Width: 2.3mm Band Thickness: from 2.5mm to 1.9mm If you have any special requests for this design (such as metal, gemstone, or design details), please contact our advisor for customization. Description Elegant, radiant, and beautifully sculptural, this wedding ring enhancer features shimmering round-cut lab diamonds set in refined French pavé detailing along a graceful V-shaped silhouette . Designed to contour elegantly around an engagement ring, the enhancer creates a luminous layered look filled with timeless… | F37: 18K Gold | G37: Lab Grown Diamond | I37: 1.8mm (per stone) | J37: 1.8mm round cut DEF VS | K37: 1401 | L37: =K37*(1-Pricing!$B$4) | M37: =L37*Pricing!$B$9*(1+Pricing!$B$6+Pricing!$B$7)+Pricing!$B$5 | N37: =M37*(1+Pricing!$B$8) | O37: =N37-M37 | P37: View Product | Q37: Fiorese Jewelry | R37: Open Image | S37: 1
A38: 35 | C38: Round & Marquise-Cut Lab Diamond Eternity Ring with Shared-Prong Setting | D38: Engagement Ring | E38: Stone Type: Lab Diamond Stone Spec: 2mm round cut and 4*2mm marquise cut DEF VS If you have any special requests for this design (such as metal, gemstone, or design details), please contact our advisor for customization. Description Elegant, romantic, and beautifully distinctive, this eternity ring features an alternating arrangement of round and marquise-cut lab diamonds secured in refined shared-prong settings , creating a graceful rhythm of brilliance and elongated elegance around the finger. The combination of diamond shapes evokes the beauty of blooming petals and delicate leaf motifs… | F38: 18K Gold | G38: Lab Grown Diamond | I38: 4×2mm (per stone) | J38: 2mm Round Cut and 4*2mm Marquise Cut DEF VS | K38: 1414.5 | L38: =K38*(1-Pricing!$B$4) | M38: =L38*Pricing!$B$9*(1+Pricing!$B$6+Pricing!$B$7)+Pricing!$B$5 | N38: =M38*(1+Pricing!$B$8) | O38: =N38-M38 | P38: View Product | Q38: Fiorese Jewelry | R38: Open Image | S38: 1
A39: 36 | C39: Round-Cut Lab Diamond V-Shaped Wedding Ring Enhancer with U-Shaped Pavé | D39: Engagement Ring | E39: Stone Type: Lab Diamond Stone Spec: 1.9mm round cut DEF VS (half eternity ) Band Width: 2mm Band Thickness: From 2mm to 1.5mm If you have any special requests for this design (such as metal, gemstone, or design details), please contact our advisor for customization. Description Elegant, luminous, and beautifully sculptural, this wedding ring enhancer features shimmering round-cut lab diamonds set within a refined U-shaped pavé design , forming a graceful V-shaped silhouette that contours elegantly around an engagement ring. The flowing shape enhances the center ring with added brilliance,… | F39: 18K Gold | G39: Lab Grown Diamond | I39: 1.9mm (per stone) | J39: 1.9mm round cut DEF VS | K39: 1485.75 | L39: =K39*(1-Pricing!$B$4) | M39: =L39*Pricing!$B$9*(1+Pricing!$B$6+Pricing!$B$7)+Pricing!$B$5 | N39: =M39*(1+Pricing!$B$8) | O39: =N39-M39 | P39: View Product | Q39: Fiorese Jewelry | R39: Open Image | S39: 1
A40: 37 | C40: Asscher-Cut Lab Diamond 7-Stone Half Eternity Ring with Bezel | D40: Engagement Ring | E40: Stone Type: Lab Diamond Stone Spec: 2.5*2.5mm asscher cut DEF VS Band Width: 1.8mm Band Thickness: 1.8mm If you have any special requests for this design (such as metal, gemstone, or design details), please contact our advisor for customization. Description Elegant, bold, and impeccably refined, this 7-stone half eternity ring features luminous Asscher-cut lab diamonds framed within sleek bezel settings , creating a sophisticated composition inspired by timeless Art Deco glamour. The Asscher cuts showcase crisp geometric symmetry and mesmerizing step-cut reflections, delivering understated… | F40: 18K Gold | G40: Lab Grown Diamond | I40: 2.5×2.5mm (per stone) | J40: 7 pieces of 2.5*2.5mm Asscher Cut DEF VS | K40: 1551.75 | L40: =K40*(1-Pricing!$B$4) | M40: =L40*Pricing!$B$9*(1+Pricing!$B$6+Pricing!$B$7)+Pricing!$B$5 | N40: =M40*(1+Pricing!$B$8) | O40: =N40-M40 | P40: View Product | Q40: Fiorese Jewelry | R40: Open Image | S40: 2
A41: 38 | C41: Baguette-Cut Lab Diamond 7-Stone Half Eternity Ring | D41: Engagement Ring | E41: Stone Spec: 7 pieces of 3*1.5mm baguette cut lab diamond DEF VS Band Width: 2mm Band Thickness: 1.8mm If you have any special requests for this design (such as metal, gemstone, or design details), please contact our advisor for customization. Description Modern, sculptural, and elegantly refined, this 7-stone half eternity ring features luminous baguette-cut lab diamonds arranged in a graceful wave-inspired design , creating a fluid balance between geometric precision and organic movement. The sleek baguette cuts deliver crisp linear reflections with understated sophistication and… | F41: 18K Gold | G41: Lab Grown Diamond | I41: 3×1.5mm (per stone) | J41: 7 pieces of 3*1.5 mm Baguette Cut DEF VVS-VS | K41: 1596.75 | L41: =K41*(1-Pricing!$B$4) | M41: =L41*Pricing!$B$9*(1+Pricing!$B$6+Pricing!$B$7)+Pricing!$B$5 | N41: =M41*(1+Pricing!$B$8) | O41: =N41-M41 | P41: View Product | Q41: Fiorese Jewelry | R41: Open Image | S41: 1
...

Sheet Pricing
A1: PRICING MODEL — edit the yellow cells only
A3: WHAT YOU PAY
A4: Wholesale discount off the listed price | B4: 0 | C4: THE MAIN LEVER. The listed prices are the sites’ RETAIL prices. Ask each supplier for their wholesale / OEM rate and enter it here (e.g. 40% means you pay 60% of the listed price). At 0% you are paying full retail and cannot price competitively.
A5: Shipping & insurance per piece (SAR) | B5: 0 | C5: A flat amount added to every piece.
A6: Customs, duty & VAT | B6: 0 | C6: Percentage added on the landed value.
A7: Payment / bank / platform fees | B7: 0 | C7: Card, transfer or marketplace fees.
A8: Profit margin | B8: 0.1 | C8: Your profit as a percentage ON TOP OF your landed cost (mark-up). 10% here = 9.1% of the selling price.
A9: USD → SAR exchange rate | B9: 3.75 | C9: Official Saudi riyal peg.
A12: HOW EACH PRICE IS BUILT
A13: 1. Your Cost (USD) | C13: Listed Price × (1 − wholesale discount)
A14: 2. Landed Cost (SAR) | C14: Your Cost × exchange rate × (1 + customs + fees) + shipping
A15: 3. FINAL PRICE (SAR) | C15: Landed Cost × (1 + profit margin)
A16: 4. Profit (SAR) | C16: Final Price − Landed Cost
A18: ⚠ The listed prices are RETAIL prices published on consumer websites, not wholesale. Selling at a 5–10% margin on top of full retail is not viable — the number you need is the wholesale discount in cell B4. All three suppliers run B2B / OEM programmes (Provence Gems is itself the manufacturer), and StarsGem prices by quotation only, which is why it carries no public prices at all.

Sheet Summary & Method
A1: LAB DIAMOND JEWELRY — EXTRACTION SUMMARY
A3: Markup multiplier (price + 110%) | B3: 2.1
A4: USD → SAR exchange rate | B4: 3.75
A5: Edit either yellow cell and every FINAL PRICE (SAR) recalculates.
A7: Unique items listed | B7: 1173
A8: Price range (USD) | B8: $119.00 – $109,251.00
A9: Average price | B9: $3,257.98
A10: Final price | B10: FINAL PRICE (SAR) = Price (USD) × 2.10 × 3.75 — cost + 110%, converted at the official Saudi riyal peg
A11: Final price range | B11: 937 – 860,352 SAR
A13: SOURCES
A14: Fiorese Jewelry | B14: 655 items · https://fioresejewelry.com/
A15: Provence Gems | B15: 306 items · https://provencegems.com/
A16: LGG Jewelry | B16: 212 items · https://www.lggjewelry.com/
A17: StarsGem (EXCLUDED) | B17: https://www.starsgem.com/ — removed: the site is quote-only and publishes no prices, so price and final-price columns could not be filled.
A19: BREAKDOWN BY METAL
A20: 18K Gold | B20: 1103 items
A21: 925 Silver | B21: 70 items
A23: BREAKDOWN BY CATEGORY
A24: Engagement Ring | B24: 312 items
A25: Stud Earrings | B25: 174 items
A26: Necklace | B26: 159 items
A27: Tennis Bracelet | B27: 129 items
A28: Ring | B28: 111 items
A29: Tennis Necklace | B29: 90 items
A30: Pendant | B30: 46 items
A31: Wedding/Eternity Band | B31: 43 items
A32: Bracelet | B32: 39 items
A33: Hoop Earrings | B33: 36 items
A34: Earrings | B34: 29 items
A35: Jewelry | B35: 5 items
A37: FILTERS & METHOD
A38: Metal filter | B38: Only solid 18K gold (white / yellow / rose) or 925 sterling silver. 10K, 14K, platinum and PT950 options were excluded.
A39: Stone filter | B39: Only jewelry whose MAIN / centre stone is a lab-grown diamond. Moissanite, cubic zirconia, lab sapphire / ruby / emerald / paraiba / padparadscha, moss agate and other gemstones were excluded, including pieces where a lab diamond appears only as a side stone.
A40: Scope | B40: Finished jewelry only — loose stones, melee and per-carat parcels excluded.
A41: Duplicate handling | B41: Items were grouped by design + metal + carat weight. Ring sizes, chain lengths and gold colours collapse into one row and the CHEAPEST qualifying option is the one listed. "Variants Merged" shows how many options were collapsed.
A42: 18K vs 925 | B42: Where a design is offered in both 18K gold and 925 silver, both appear as separate rows — they are different products at different prices, not duplicates.
A43: Weight | B43: "Weight (ct)" is the total lab-diamond carat weight taken from the product option or title. Blank where the seller does not state it. "Stone Size" gives the stone dimensions in mm where quoted instead.
A44: Price basis | B44: Lowest listed price of the qualifying option, in USD, as published at extraction time. Excludes shipping, duties and any customisation surcharge.
A45: Quote-only variants | B45: Variants priced as placeholders (e.g. "other carat weight", custom orders) were removed.
A46: Extracted | B46: 2026-09-04
